Workbook

Sheet Scouting Notes
B1: Murray State scouting notes, for the exhibition on Thursday, Oct 22, 2026
B2: Built from 5 box scores: Team Barcelona (Aug 4), Maroussi BC (Aug 8), France (Aug 10), at Wichita State (Oct 7), vs Incarnate Word (Oct 18).
B4: Record | C4: 5–0 (2–0 in October)
B5: Points per game | C5: =AVERAGE('Team Game Log'!D5:D9) -> 95.8
B6: Points allowed per game (4 games with opponent data) | C6: =AVERAGE('Team Game Log'!E5:E9) -> 72.25
B7: Opponent turnovers per game | C7: =AVERAGE('Team Game Log'!AC5:AC9) -> 22.75
B8: Steals per game | C8: =AVERAGE('Team Game Log'!Q5:Q9) -> 15.4
B9: Team 3PT% | C9: =SUM('Team Game Log'!I5:I9)/SUM('Team Game Log'!J5:J9) -> 0.31481481
B11: Keys for the staff
A12: 1 | B12: Ball security is the game. | C12: They forced 22.8 turnovers per game (28% of opponent possessions) and averaged 15.4 steals. Wichita State kept it to 15 turnovers and was the only team to stay close (93–87).
A13: 2 | B13: Domon (#77) is the focal point. | C13: 21.2 ppg, 23.5 in October, 30 vs UIW. 26-30 FT but 6-30 from three (20%). Keep him out of the lane, don't foul, make him shoot threes.
A14: 3 | B14: Run Shorter (#34) off the line. | C14: 29 of his 35 shots are threes (10-29, 34%). 4-7 from three at Wichita State.
A15: 4 | B15: Attack Rogers (#11). | C15: Starter and top rebounder (6.6 rpg), but 25 fouls in 5 games, 0 three-point attempts, 8-14 FT.
A16: 5 | B16: Pressure Magwood (#0). | C16: Backup PG with 20 turnovers in 5 games (4 in each October game).
A17: 6 | B17: Box out. | C17: 13 offensive rebounds per game; 36% of their own misses. 22 second-chance points vs UIW, 25 vs France.
A18: 7 | B18: Get downhill. | C18: 23.2 fouls per game. Wichita State went 26-32 at the line with 36 paint points.
A19: 8 | B19: Second-half push, deep bench. | C19: October second halves: 57 and 53 points. 10–14 players play; bench averaged 42 points.
A20: 9 | B20: Likely starting five | C20: #77 Roman Domon (F), #11 Brigham Rogers (F), #14 Lachlan Crate (F), #8 Talis Soulhac (G), #34 Brayden Shorter (G). Same five in both October games.

Sheet Player Game Log
A1: Murray State player box scores, one row per player per game
A2: Blue = values entered from the box scores (source: the scanned PDF of 5 box scores). Black = formulas. Edit blue cells only.
A4: Game | B4: Date | C4: Period | D4: Opponent | E4: # | F4: Player | G4: MIN | H4: FGM | I4: FGA | J4: 3PM | K4: 3PA | L4: FTM | M4: FTA | N4: OREB | O4: DREB | P4: REB | Q4: AST | R4: TO | S4: STL | T4: BLK | U4: PF | V4: PTS | W4: Started
A5: BAR | B5: Aug 4, 2026 | C5: Summer tour | D5: Team Barcelona | E5: 6 | F5: Christian Jones | G5: 14.9 | H5: 4 | I5: 7 | J5: 2 | K5: 3 | L5: 0 | M5: 0 | N5: 0 | O5: 2 | P5: =N5+O5 -> 2 | Q5: 0 | R5: 1 | S5: 2 | T5: 1 | U5: 5 | V5: 10 | W5: n/a
A6: BAR | B6: Aug 4, 2026 | C6: Summer tour | D6: Team Barcelona | E6: 7 | F6: Ben Shtolzberg | G6: 17.53 | H6: 2 | I6: 5 | J6: 0 | K6: 1 | L6: 1 | M6: 2 | N6: 2 | O6: 0 | P6: =N6+O6 -> 2 | Q6: 3 | R6: 2 | S6: 1 | T6: 0 | U6: 2 | V6: 5 | W6: n/a
A7: BAR | B7: Aug 4, 2026 | C7: Summer tour | D7: Team Barcelona | E7: 14 | F7: Lachlan Crate | G7: 21.98 | H7: 4 | I7: 9 | J7: 1 | K7: 4 | L7: 0 | M7: 0 | N7: 1 | O7: 6 | P7: =N7+O7 -> 7 | Q7: 3 | R7: 0 | S7: 2 | T7: 0 | U7: 3 | V7: 9 | W7: n/a
A8: BAR | B8: Aug 4, 2026 | C8: Summer tour | D8: Team Barcelona | E8: 23 | F8: Shon Tupuola | G8: 18.13 | H8: 1 | I8: 3 | J8: 0 | K8: 0 | L8: 1 | M8: 2 | N8: 1 | O8: 6 | P8: =N8+O8 -> 7 | Q8: 1 | R8: 0 | S8: 0 | T8: 1 | U8: 0 | V8: 3 | W8: n/a
A9: BAR | B9: Aug 4, 2026 | C9: Summer tour | D9: Team Barcelona | E9: 77 | F9: Roman Domon | G9: 20.58 | H9: 6 | I9: 16 | J9: 1 | K9: 6 | L9: 1 | M9: 2 | N9: 3 | O9: 3 | P9: =N9+O9 -> 6 | Q9: 2 | R9: 1 | S9: 1 | T9: 1 | U9: 4 | V9: 14 | W9: n/a
A10: BAR | B10: Aug 4, 2026 | C10: Summer tour | D10: Team Barcelona | E10: 11 | F10: Brigham Rogers | G10: 21.87 | H10: 4 | I10: 5 | J10: 0 | K10: 0 | L10: 0 | M10: 0 | N10: 2 | O10: 5 | P10: =N10+O10 -> 7 | Q10: 2 | R10: 1 | S10: 3 | T10: 0 | U10: 4 | V10: 8 | W10: n/a
A11: BAR | B11: Aug 4, 2026 | C11: Summer tour | D11: Team Barcelona | E11: 0 | F11: Kaden Magwood | G11: 20.18 | H11: 5 | I11: 11 | J11: 2 | K11: 8 | L11: 1 | M11: 2 | N11: 1 | O11: 6 | P11: =N11+O11 -> 7 | Q11: 6 | R11: 4 | S11: 1 | T11: 0 | U11: 2 | V11: 13 | W11: n/a
A12: BAR | B12: Aug 4, 2026 | C12: Summer tour | D12: Team Barcelona | E12: 2 | F12: Mathis Courbon | G12: 20.37 | H12: 7 | I12: 8 | J12: 5 | K12: 5 | L12: 2 | M12: 2 | N12: 0 | O12: 1 | P12: =N12+O12 -> 1 | Q12: 4 | R12: 1 | S12: 4 | T12: 0 | U12: 2 | V12: 21 | W12: n/a
A13: BAR | B13: Aug 4, 2026 | C13: Summer tour | D13: Team Barcelona | E13: 34 | F13: Brayden Shorter | G13: 19.53 | H13: 3 | I13: 9 | J13: 1 | K13: 7 | L13: 2 | M13: 2 | N13: 1 | O13: 1 | P13: =N13+O13 -> 2 | Q13: 2 | R13: 1 | S13: 1 | T13: 0 | U13: 1 | V13: 9 | W13: n/a
A14: BAR | B14: Aug 4, 2026 | C14: Summer tour | D14: Team Barcelona | E14: 4 | F14: Mark Padjen | G14: 18.8 | H14: 1 | I14: 6 | J14: 1 | K14: 5 | L14: 0 | M14: 0 | N14: 1 | O14: 3 | P14: =N14+O14 -> 4 | Q14: 3 | R14: 1 | S14: 2 | T14: 0 | U14: 0 | V14: 3 | W14: n/a
A15: BAR | B15: Aug 4, 2026 | C15: Summer tour | D15: Team Barcelona | E15: 13 | F15: Navon Shabazz | G15: 5.2 | H15: 0 | I15: 2 | J15: 0 | K15: 2 | L15: 0 | M15: 0 | N15: 0 | O15: 0 | P15: =N15+O15 -> 0 | Q15: 0 | R15: 0 | S15: 0 | T15: 0 | U15: 1 | V15: 0 | W15: n/a
A16: BAR | B16: Aug 4, 2026 | C16: Summer tour | D16: Team Barcelona | E16: 25 | F16: Dillon Butler | G16: 0.92 | H16: 0 | I16: 0 | J16: 0 | K16: 0 | L16: 0 | M16: 0 | N16: 0 | O16: 0 | P16: =N16+O16 -> 0 | Q16: 0 | R16: 0 | S16: 0 | T16: 0 | U16: 1 | V16: 0 | W16: n/a
A17: MAR | B17: Aug 8, 2026 | C17: Summer tour | D17: Maroussi BC | E17: 0 | F17: Kaden Magwood | H17: 4 | I17: 8 | J17: 0 | K17: 4 | L17: 1 | M17: 3 | N17: 0 | O17: 1 | P17: =N17+O17 -> 1 | Q17: 7 | R17: 5 | S17: 3 | T17: 1 | U17: 3 | V17: 9 | W17: n/a
A18: MAR | B18: Aug 8, 2026 | C18: Summer tour | D18: Maroussi BC | E18: 2 | F18: Mathis Courbon | H18: 1 | I18: 7 | J18: 0 | K18: 5 | L18: 0 | M18: 0 | N18: 2 | O18: 3 | P18: =N18+O18 -> 5 | Q18: 1 | R18: 1 | S18: 4 | T18: 1 | U18: 2 | V18: 2 | W18: n/a
A19: MAR | B19: Aug 8, 2026 | C19: Summer tour | D19: Maroussi BC | E19: 4 | F19: Mark Padjen | H19: 3 | I19: 4 | J19: 1 | K19: 2 | L19: 4 | M19: 4 | N19: 1 | O19: 5 | P19: =N19+O19 -> 6 | Q19: 2 | R19: 2 | S19: 2 | T19: 0 | U19: 2 | V19: 11 | W19: n/a
A20: MAR | B20: Aug 8, 2026 | C20: Summer tour | D20: Maroussi BC | E20: 6 | F20: Christian Jones | H20: 3 | I20: 5 | J20: 1 | K20: 3 | L20: 1 | M20: 2 | N20: 0 | O20: 3 | P20: =N20+O20 -> 3 | Q20: 1 | R20: 3 | S20: 1 | T20: 0 | U20: 3 | V20: 8 | W20: n/a
A21: MAR | B21: Aug 8, 2026 | C21: Summer tour | D21: Maroussi BC | E21: 7 | F21: Ben Shtolzberg | H21: 4 | I21: 5 | J21: 0 | K21: 0 | L21: 0 | M21: 0 | N21: 0 | O21: 3 | P21: =N21+O21 -> 3 | Q21: 3 | R21: 0 | S21: 2 | T21: 0 | U21: 3 | V21: 8 | W21: n/a
A22: MAR | B22: Aug 8, 2026 | C22: Summer tour | D22: Maroussi BC | E22: 11 | F22: Brigham Rogers | H22: 3 | I22: 6 | J22: 0 | K22: 0 | L22: 2 | M22: 5 | N22: 4 | O22: 3 | P22: =N22+O22 -> 7 | Q22: 1 | R22: 2 | S22: 0 | T22: 0 | U22: 7 | V22: 8 | W22: n/a
A23: MAR | B23: Aug 8, 2026 | C23: Summer tour | D23: Maroussi BC | E23: 14 | F23: Lachlan Crate | H23: 2 | I23: 3 | J23: 0 | K23: 0 | L23: 1 | M23: 2 | N23: 1 | O23: 2 | P23: =N23+O23 -> 3 | Q23: 0 | R23: 3 | S23: 0 | T23: 0 | U23: 3 | V23: 5 | W23: n/a
A24: MAR | B24: Aug 8, 2026 | C24: Summer tour | D24: Maroussi BC | E24: 23 | F24: Shon Tupuola | H24: 3 | I24: 5 | J24: 0 | K24: 0 | L24: 1 | M24: 4 | N24: 0 | O24: 3 | P24: =N24+O24 -> 3 | Q24: 0 | R24: 0 | S24: 2 | T24: 0 | U24: 1 | V24: 7 | W24: n/a
A25: MAR | B25: Aug 8, 2026 | C25: Summer tour | D25: Maroussi BC | E25: 34 | F25: Brayden Shorter | H25: 3 | I25: 6 | J25: 3 | K25: 6 | L25: 0 | M25: 0 | N25: 0 | O25: 1 | P25: =N25+O25 -> 1 | Q25: 2 | R25: 1 | S25: 2 | T25: 0 | U25: 1 | V25: 9 | W25: n/a
A26: MAR | B26: Aug 8, 2026 | C26: Summer tour | D26: Maroussi BC | E26: 77 | F26: Roman Domon | H26: 7 | I26: 17 | J26: 0 | K26: 8 | L26: 7 | M26: 8 | N26: 0 | O26: 4 | P26: =N26+O26 -> 4 | Q26: 4 | R26: 4 | S26: 5 | T26: 1 | U26: 2 | V26: 21 | W26: n/a
A27: FRA | B27: Aug 10, 2026 | C27: Summer tour | D27: France | E27: 0 | F27: Kaden Magwood | G27: 18 | H27: 7 | I27: 12 | J27: 4 | K27: 8 | L27: 0 | M27: 0 | N27: 0 | O27: 3 | P27: =N27+O27 -> 3 | Q27: 2 | R27: 3 | S27: 1 | T27: 0 | U27: 0 | V27: 18 | W27: No
A28: FRA | B28: Aug 10, 2026 | C28: Summer tour | D28: France | E28: 2 | F28: Mathis Courbon | G28: 19.35 | H28: 6 | I28: 10 | J28: 3 | K28: 6 | L28: 0 | M28: 0 | N28: 2 | O28: 1 | P28: =N28+O28 -> 3 | Q28: 3 | R28: 0 | S28: 3 | T28: 0 | U28: 1 | V28: 15 | W28: Yes
A29: FRA | B29: Aug 10, 2026 | C29: Summer tour | D29: France | E29: 4 | F29: Mark Padjen | G29: 19.92 | H29: 1 | I29: 5 | J29: 1 | K29: 4 | L29: 0 | M29: 0 | N29: 1 | O29: 1 | P29: =N29+O29 -> 2 | Q29: 2 | R29: 0 | S29: 2 | T29: 0 | U29: 2 | V29: 3 | W29: No
A30: FRA | B30: Aug 10, 2026 | C30: Summer tour | D30: France | E30: 6 | F30: Christian Jones | G30: 22.22 | H30: 4 | I30: 9 | J30: 2 | K30: 4 | L30: 3 | M30: 3 | N30: 0 | O30: 4 | P30: =N30+O30 -> 4 | Q30: 2 | R30: 2 | S30: 2 | T30: 0 | U30: 3 | V30: 13 | W30: Yes
A31: FRA | B31: Aug 10, 2026 | C31: Summer tour | D31: France | E31: 7 | F31: Ben Shtolzberg | G31: 17 | H31: 6 | I31: 10 | J31: 1 | K31: 3 | L31: 1 | M31: 1 | N31: 1 | O31: 1 | P31: =N31+O31 -> 2 | Q31: 2 | R31: 2 | S31: 2 | T31: 1 | U31: 5 | V31: 14 | W31: No
A32: FRA | B32: Aug 10, 2026 | C32: Summer tour | D32: France | E32: 11 | F32: Brigham Rogers | G32: 22.03 | H32: 3 | I32: 4 | J32: 0 | K32: 0 | L32: 1 | M32: 2 | N32: 3 | O32: 5 | P32: =N32+O32 -> 8 | Q32: 5 | R32: 3 | S32: 3 | T32: 1 | U32: 9 | V32: 7 | W32: No
A33: FRA | B33: Aug 10, 2026 | C33: Summer tour | D33: France | E33: 13 | F33: Navon Shabazz | G33: 3.48 | H33: 0 | I33: 1 | J33: 0 | K33: 1 | L33: 0 | M33: 0 | N33: 0 | O33: 1 | P33: =N33+O33 -> 1 | Q33: 0 | R33: 0 | S33: 0 | T33: 0 | U33: 0 | V33: 0 | W33: No
A34: FRA | B34: Aug 10, 2026 | C34: Summer tour | D34: France | E34: 14 | F34: Lachlan Crate | G34: 20.47 | H34: 3 | I34: 5 | J34: 0 | K34: 0 | L34: 3 | M34: 4 | N34: 2 | O34: 3 | P34: =N34+O34 -> 5 | Q34: 1 | R34: 0 | S34: 1 | T34: 0 | U34: 1 | V34: 9 | W34: Yes
A35: FRA | B35: Aug 10, 2026 | C35: Summer tour | D35: France | E35: 23 | F35: Shon Tupuola | G35: 17.97 | H35: 1 | I35: 3 | J35: 0 | K35: 1 | L35: 0 | M35: 0 | N35: 1 | O35: 5 | P35: =N35+O35 -> 6 | Q35: 2 | R35: 0 | S35: 0 | T35: 0 | U35: 0 | V35: 2 | W35: Yes
A36: FRA | B36: Aug 10, 2026 | C36: Summer tour | D36: France | E36: 25 | F36: Dillon Butler | G36: 1.48 | H36: 0 | I36: 1 | J36: 0 | K36: 0 | L36: 0 | M36: 0 | N36: 0 | O36: 0 | P36: =N36+O36 -> 0 | Q36: 0 | R36: 0 | S36: 0 | T36: 0 | U36: 0 | V36: 0 | W36: No
A37: FRA | B37: Aug 10, 2026 | C37: Summer tour | D37: France | E37: 34 | F37: Brayden Shorter | G37: 15.22 | H37: 2 | I37: 9 | J37: 1 | K37: 6 | L37: 0 | M37: 0 | N37: 3 | O37: 1 | P37: =N37+O37 -> 4 | Q37: 4 | R37: 0 | S37: 3 | T37: 0 | U37: 0 | V37: 5 | W37: No
A38: FRA | B38: Aug 10, 2026 | C38: Summer tour | D38: France | E38: 77 | F38: Roman Domon | G38: 22.87 | H38: 9 | I38: 17 | J38: 2 | K38: 6 | L38: 4 | M38: 4 | N38: 3 | O38: 1 | P38: =N38+O38 -> 4 | Q38: 2 | R38: 1 | S38: 2 | T38: 0 | U38: 2 | V38: 24 | W38: Yes
... A62: UIW | B62: Oct 18, 2026 | C62: October | D62: vs Incarnate Word | E62: 25 | F62: Dillon Butler | G62: 1.63 | H62: 0 | I62: 1 | J62: 0 | K62: 0 | L62: 0 | M62: 0 | N62: 0 | O62: 0 | P62: =N62+O62 -> 0 | Q62: 0 | R62: 0 | S62: 0 | T62: 0 | U62: 0 | V62: 0 | W62: No
A64: MIN is in decimal minutes (20:35 = 20.6). The Maroussi BC sheet had no minutes, so MIN is blank for that game. Players who show all zeros on the Maroussi sheet are left out of it.

Sheet Combined Stats
A1: Murray State: combined player stats, all 5 games
A2: Every number below is a formula over the Player Game Log tab. Per-game = total ÷ GP. MPG uses only games with minutes recorded.
A4: # | B4: Player | C4: GP | D4: GS | E4: MIN | F4: MPG | G4: PTS | H4: PPG | I4: REB | J4: RPG | K4: OREB | L4: AST | M4: APG | N4: TO | O4: TOPG | P4: STL | Q4: SPG | R4: BLK | S4: PF | T4: PF/G | U4: FGM | V4: FGA | W4: FG% | X4: 3PM | Y4: 3PA | Z4: 3P% | AA4: FTM | AB4: FTA | AC4: FT% | AD4: eFG% | AE4: TS% | AF4: PTS/40
A5: 77 | B5: Roman Domon | C5: =COUNTIFS('Player Game Log'!$F$5:$F$62,$B5) -> 5 | D5: =COUNTIFS('Player Game Log'!$F$5:$F$62,$B5,'Player Game Log'!$W$5:$W$62,"Yes") -> 3 | E5: =SUMIFS('Player Game Log'!$G$5:$G$62,'Player Game Log'!$F$5:$F$62,$B5) -> 101.78 | F5: =IFERROR(E5/COUNTIFS('Player Game Log'!$F$5:$F$62,$B5,'Player Game Log'!$G$5:$G$62,"<>"),"") -> 25.445 | G5: =SUMIFS('Player Game Log'!$V$5:$V$62,'Player Game Log'!$F$5:$F$62,$B5) -> 106 | H5: =G5/C5 -> 21.2 | I5: =SUMIFS('Player Game Log'!$P$5:$P$62,'Player Game Log'!$F$5:$F$62,$B5) -> 19 | J5: =I5/C5 -> 3.8 | K5: =SUMIFS('Player Game Log'!$N$5:$N$62,'Player Game Log'!$F$5:$F$62,$B5) -> 6 | L5: =SUMIFS('Player Game Log'!$Q$5:$Q$62,'Player Game Log'!$F$5:$F$62,$B5) -> 15 | M5: =L5/C5 -> 3 | N5: =SUMIFS('Player Game Log'!$R$5:$R$62,'Player Game Log'!$F$5:$F$62,$B5) -> 13 | O5: =N5/C5 -> 2.6 | P5: =SUMIFS('Player Game Log'!$S$5:$S$62,'Player Game Log'!$F$5:$F$62,$B5) -> 14 | Q5: =P5/C5 -> 2.8 | R5: =SUMIFS('Player Game Log'!$T$5:$T$62,'Player Game Log'!$F$5:$F$62,$B5) -> 3 | S5: =SUMIFS('Player Game Log'!$U$5:$U$62,'Player Game Log'!$F$5:$F$62,$B5) -> 14 | T5: =S5/C5 -> 2.8 | U5: =SUMIFS('Player Game Log'!$H$5:$H$62,'Player Game Log'!$F$5:$F$62,$B5) -> 37 | V5: =SUMIFS('Player Game Log'!$I$5:$I$62,'Player Game Log'!$F$5:$F$62,$B5) -> 77 | W5: =IF(V5=0,"",U5/V5) -> 0.48051948 | X5: =SUMIFS('Player Game Log'!$J$5:$J$62,'Player Game Log'!$F$5:$F$62,$B5) -> 6 | Y5: =SUMIFS('Player Game Log'!$K$5:$K$62,'Player Game Log'!$F$5:$F$62,$B5) -> 30 | Z5: =IF(Y5=0,"",X5/Y5) -> 0.2 | AA5: =SUMIFS('Player Game Log'!$L$5:$L$62,'Player Game Log'!$F$5:$F$62,$B5) -> 26 | AB5: =SUMIFS('Player Game Log'!$M$5:$M$62,'Player Game Log'!$F$5:$F$62,$B5) -> 30 | AC5: =IF(AB5=0,"",AA5/AB5) -> 0.86666667 | AD5: =IF(V5=0,"",(U5+0.5*X5)/V5) -> 0.51948052 | AE5: =IF(V5+AB5=0,"",G5/(2*(V5+0.44*AB5))) -> 0.58758315 | AF5: =IF(E5=0,"",G5/E5*40) -> 41.658479
A6: 0 | B6: Kaden Magwood | C6: =COUNTIFS('Player Game Log'!$F$5:$F$62,$B6) -> 5 | D6: =COUNTIFS('Player Game Log'!$F$5:$F$62,$B6,'Player Game Log'!$W$5:$W$62,"Yes") -> 0 | E6: =SUMIFS('Player Game Log'!$G$5:$G$62,'Player Game Log'!$F$5:$F$62,$B6) -> 71.26 | F6: =IFERROR(E6/COUNTIFS('Player Game Log'!$F$5:$F$62,$B6,'Player Game Log'!$G$5:$G$62,"<>"),"") -> 17.815 | G6: =SUMIFS('Player Game Log'!$V$5:$V$62,'Player Game Log'!$F$5:$F$62,$B6) -> 56 | H6: =G6/C6 -> 11.2 | I6: =SUMIFS('Player Game Log'!$P$5:$P$62,'Player Game Log'!$F$5:$F$62,$B6) -> 17 | J6: =I6/C6 -> 3.4 | K6: =SUMIFS('Player Game Log'!$N$5:$N$62,'Player Game Log'!$F$5:$F$62,$B6) -> 2 | L6: =SUMIFS('Player Game Log'!$Q$5:$Q$62,'Player Game Log'!$F$5:$F$62,$B6) -> 17 | M6: =L6/C6 -> 3.4 | N6: =SUMIFS('Player Game Log'!$R$5:$R$62,'Player Game Log'!$F$5:$F$62,$B6) -> 20 | O6: =N6/C6 -> 4 | P6: =SUMIFS('Player Game Log'!$S$5:$S$62,'Player Game Log'!$F$5:$F$62,$B6) -> 9 | Q6: =P6/C6 -> 1.8 | R6: =SUMIFS('Player Game Log'!$T$5:$T$62,'Player Game Log'!$F$5:$F$62,$B6) -> 1 | S6: =SUMIFS('Player Game Log'!$U$5:$U$62,'Player Game Log'!$F$5:$F$62,$B6) -> 10 | T6: =S6/C6 -> 2 | U6: =SUMIFS('Player Game Log'!$H$5:$H$62,'Player Game Log'!$F$5:$F$62,$B6) -> 22 | V6: =SUMIFS('Player Game Log'!$I$5:$I$62,'Player Game Log'!$F$5:$F$62,$B6) -> 43 | W6: =IF(V6=0,"",U6/V6) -> 0.51162791 | X6: =SUMIFS('Player Game Log'!$J$5:$J$62,'Player Game Log'!$F$5:$F$62,$B6) -> 9 | Y6: =SUMIFS('Player Game Log'!$K$5:$K$62,'Player Game Log'!$F$5:$F$62,$B6) -> 26 | Z6: =IF(Y6=0,"",X6/Y6) -> 0.34615385 | AA6: =SUMIFS('Player Game Log'!$L$5:$L$62,'Player Game Log'!$F$5:$F$62,$B6) -> 3 | AB6: =SUMIFS('Player Game Log'!$M$5:$M$62,'Player Game Log'!$F$5:$F$62,$B6) -> 8 | AC6: =IF(AB6=0,"",AA6/AB6) -> 0.375 | AD6: =IF(V6=0,"",(U6+0.5*X6)/V6) -> 0.61627907 | AE6: =IF(V6+AB6=0,"",G6/(2*(V6+0.44*AB6))) -> 0.60189166 | AF6: =IF(E6=0,"",G6/E6*40) -> 31.434185
A7: 6 | B7: Christian Jones | C7: =COUNTIFS('Player Game Log'!$F$5:$F$62,$B7) -> 5 | D7: =COUNTIFS('Player Game Log'!$F$5:$F$62,$B7,'Player Game Log'!$W$5:$W$62,"Yes") -> 1 | E7: =SUMIFS('Player Game Log'!$G$5:$G$62,'Player Game Log'!$F$5:$F$62,$B7) -> 76.99 | F7: =IFERROR(E7/COUNTIFS('Player Game Log'!$F$5:$F$62,$B7,'Player Game Log'!$G$5:$G$62,"<>"),"") -> 19.2475 | G7: =SUMIFS('Player Game Log'!$V$5:$V$62,'Player Game Log'!$F$5:$F$62,$B7) -> 53 | H7: =G7/C7 -> 10.6 | I7: =SUMIFS('Player Game Log'!$P$5:$P$62,'Player Game Log'!$F$5:$F$62,$B7) -> 16 | J7: =I7/C7 -> 3.2 | K7: =SUMIFS('Player Game Log'!$N$5:$N$62,'Player Game Log'!$F$5:$F$62,$B7) -> 2 | L7: =SUMIFS('Player Game Log'!$Q$5:$Q$62,'Player Game Log'!$F$5:$F$62,$B7) -> 10 | M7: =L7/C7 -> 2 | N7: =SUMIFS('Player Game Log'!$R$5:$R$62,'Player Game Log'!$F$5:$F$62,$B7) -> 10 | O7: =N7/C7 -> 2 | P7: =SUMIFS('Player Game Log'!$S$5:$S$62,'Player Game Log'!$F$5:$F$62,$B7) -> 8 | Q7: =P7/C7 -> 1.6 | R7: =SUMIFS('Player Game Log'!$T$5:$T$62,'Player Game Log'!$F$5:$F$62,$B7) -> 1 | S7: =SUMIFS('Player Game Log'!$U$5:$U$62,'Player Game Log'!$F$5:$F$62,$B7) -> 15 | T7: =S7/C7 -> 3 | U7: =SUMIFS('Player Game Log'!$H$5:$H$62,'Player Game Log'!$F$5:$F$62,$B7) -> 19 | V7: =SUMIFS('Player Game Log'!$I$5:$I$62,'Player Game Log'!$F$5:$F$62,$B7) -> 40 | W7: =IF(V7=0,"",U7/V7) -> 0.475 | X7: =SUMIFS('Player Game Log'!$J$5:$J$62,'Player Game Log'!$F$5:$F$62,$B7) -> 7 | Y7: =SUMIFS('Player Game Log'!$K$5:$K$62,'Player Game Log'!$F$5:$F$62,$B7) -> 19 | Z7: =IF(Y7=0,"",X7/Y7) -> 0.36842105 | AA7: =SUMIFS('Player Game Log'!$L$5:$L$62,'Player Game Log'!$F$5:$F$62,$B7) -> 8 | AB7: =SUMIFS('Player Game Log'!$M$5:$M$62,'Player Game Log'!$F$5:$F$62,$B7) -> 9 | AC7: =IF(AB7=0,"",AA7/AB7) -> 0.88888889 | AD7: =IF(V7=0,"",(U7+0.5*X7)/V7) -> 0.5625 | AE7: =IF(V7+AB7=0,"",G7/(2*(V7+0.44*AB7))) -> 0.60282075 | AF7: =IF(E7=0,"",G7/E7*40) -> 27.536044
A8: 16 | B8: Jonas Boulefaa | C8: =COUNTIFS('Player Game Log'!$F$5:$F$62,$B8) -> 1 | D8: =COUNTIFS('Player Game Log'!$F$5:$F$62,$B8,'Player Game Log'!$W$5:$W$62,"Yes") -> 0 | E8: =SUMIFS('Player Game Log'!$G$5:$G$62,'Player Game Log'!$F$5:$F$62,$B8) -> 9.27 | F8: =IFERROR(E8/COUNTIFS('Player Game Log'!$F$5:$F$62,$B8,'Player Game Log'!$G$5:$G$62,"<>"),"") -> 9.27 | G8: =SUMIFS('Player Game Log'!$V$5:$V$62,'Player Game Log'!$F$5:$F$62,$B8) -> 10 | H8: =G8/C8 -> 10 | I8: =SUMIFS('Player Game Log'!$P$5:$P$62,'Player Game Log'!$F$5:$F$62,$B8) -> 4 | J8: =I8/C8 -> 4 | K8: =SUMIFS('Player Game Log'!$N$5:$N$62,'Player Game Log'!$F$5:$F$62,$B8) -> 3 | L8: =SUMIFS('Player Game Log'!$Q$5:$Q$62,'Player Game Log'!$F$5:$F$62,$B8) -> 0 | M8: =L8/C8 -> 0 | N8: =SUMIFS('Player Game Log'!$R$5:$R$62,'Player Game Log'!$F$5:$F$62,$B8) -> 0 | O8: =N8/C8 -> 0 | P8: =SUMIFS('Player Game Log'!$S$5:$S$62,'Player Game Log'!$F$5:$F$62,$B8) -> 1 | Q8: =P8/C8 -> 1 | R8: =SUMIFS('Player Game Log'!$T$5:$T$62,'Player Game Log'!$F$5:$F$62,$B8) -> 0 | S8: =SUMIFS('Player Game Log'!$U$5:$U$62,'Player Game Log'!$F$5:$F$62,$B8) -> 0 | T8: =S8/C8 -> 0 | U8: =SUMIFS('Player Game Log'!$H$5:$H$62,'Player Game Log'!$F$5:$F$62,$B8) -> 4 | V8: =SUMIFS('Player Game Log'!$I$5:$I$62,'Player Game Log'!$F$5:$F$62,$B8) -> 6 | W8: =IF(V8=0,"",U8/V8) -> 0.66666667 | X8: =SUMIFS('Player Game Log'!$J$5:$J$62,'Player Game Log'!$F$5:$F$62,$B8) -> 2 | Y8: =SUMIFS('Player Game Log'!$K$5:$K$62,'Player Game Log'!$F$5:$F$62,$B8) -> 4 | Z8: =IF(Y8=0,"",X8/Y8) -> 0.5 | AA8: =SUMIFS('Player Game Log'!$L$5:$L$62,'Player Game Log'!$F$5:$F$62,$B8) -> 0 | AB8: =SUMIFS('Player Game Log'!$M$5:$M$62,'Player Game Log'!$F$5:$F$62,$B8) -> 0 | AC8: =IF(AB8=0,"",AA8/AB8) | AD8: =IF(V8=0,"",(U8+0.5*X8)/V8) -> 0.83333333 | AE8: =IF(V8+AB8=0,"",G8/(2*(V8+0.44*AB8))) -> 0.83333333 | AF8: =IF(E8=0,"",G8/E8*40) -> 43.149946
A9: 14 | B9: Lachlan Crate | C9: =COUNTIFS('Player Game Log'!$F$5:$F$62,$B9) -> 5 | D9: =COUNTIFS('Player Game Log'!$F$5:$F$62,$B9,'Player Game Log'!$W$5:$W$62,"Yes") -> 3 | E9: =SUMIFS('Player Game Log'!$G$5:$G$62,'Player Game Log'!$F$5:$F$62,$B9) -> 87.03 | F9: =IFERROR(E9/COUNTIFS('Player Game Log'!$F$5:$F$62,$B9,'Player Game Log'!$G$5:$G$62,"<>"),"") -> 21.7575 | G9: =SUMIFS('Player Game Log'!$V$5:$V$62,'Player Game Log'!$F$5:$F$62,$B9) -> 44 | H9: =G9/C9 -> 8.8 | I9: =SUMIFS('Player Game Log'!$P$5:$P$62,'Player Game Log'!$F$5:$F$62,$B9) -> 21 | J9: =I9/C9 -> 4.2 | K9: =SUMIFS('Player Game Log'!$N$5:$N$62,'Player Game Log'!$F$5:$F$62,$B9) -> 8 | L9: =SUMIFS('Player Game Log'!$Q$5:$Q$62,'Player Game Log'!$F$5:$F$62,$B9) -> 5 | M9: =L9/C9 -> 1 | N9: =SUMIFS('Player Game Log'!$R$5:$R$62,'Player Game Log'!$F$5:$F$62,$B9) -> 4 | O9: =N9/C9 -> 0.8 | P9: =SUMIFS('Player Game Log'!$S$5:$S$62,'Player Game Log'!$F$5:$F$62,$B9) -> 3 | Q9: =P9/C9 -> 0.6 | R9: =SUMIFS('Player Game Log'!$T$5:$T$62,'Player Game Log'!$F$5:$F$62,$B9) -> 0 | S9: =SUMIFS('Player Game Log'!$U$5:$U$62,'Player Game Log'!$F$5:$F$62,$B9) -> 13 | T9: =S9/C9 -> 2.6 | U9: =SUMIFS('Player Game Log'!$H$5:$H$62,'Player Game Log'!$F$5:$F$62,$B9) -> 17 | V9: =SUMIFS('Player Game Log'!$I$5:$I$62,'Player Game Log'!$F$5:$F$62,$B9) -> 28 | W9: =IF(V9=0,"",U9/V9) -> 0.60714286 | X9: =SUMIFS('Player Game Log'!$J$5:$J$62,'Player Game Log'!$F$5:$F$62,$B9) -> 2 | Y9: =SUMIFS('Player Game Log'!$K$5:$K$62,'Player Game Log'!$F$5:$F$62,$B9) -> 6 | Z9: =IF(Y9=0,"",X9/Y9) -> 0.33333333 | AA9: =SUMIFS('Player Game Log'!$L$5:$L$62,'Player Game Log'!$F$5:$F$62,$B9) -> 8 | AB9: =SUMIFS('Player Game Log'!$M$5:$M$62,'Player Game Log'!$F$5:$F$62,$B9) -> 12 | AC9: =IF(AB9=0,"",AA9/AB9) -> 0.66666667 | AD9: =IF(V9=0,"",(U9+0.5*X9)/V9) -> 0.64285714 | AE9: =IF(V9+AB9=0,"",G9/(2*(V9+0.44*AB9))) -> 0.66105769 | AF9: =IF(E9=0,"",G9/E9*40) -> 20.222912
A10: 2 | B10: Mathis Courbon | C10: =COUNTIFS('Player Game Log'!$F$5:$F$62,$B10) -> 5 | D10: =COUNTIFS('Player Game Log'!$F$5:$F$62,$B10,'Player Game Log'!$W$5:$W$62,"Yes") -> 1 | E10: =SUMIFS('Player Game Log'!$G$5:$G$62,'Player Game Log'!$F$5:$F$62,$B10) -> 79.8 | F10: =IFERROR(E10/COUNTIFS('Player Game Log'!$F$5:$F$62,$B10,'Player Game Log'!$G$5:$G$62,"<>"),"") -> 19.95 | G10: =SUMIFS('Player Game Log'!$V$5:$V$62,'Player Game Log'!$F$5:$F$62,$B10) -> 44 | H10: =G10/C10 -> 8.8 | I10: =SUMIFS('Player Game Log'!$P$5:$P$62,'Player Game Log'!$F$5:$F$62,$B10) -> 12 | J10: =I10/C10 -> 2.4 | K10: =SUMIFS('Player Game Log'!$N$5:$N$62,'Player Game Log'!$F$5:$F$62,$B10) -> 5 | L10: =SUMIFS('Player Game Log'!$Q$5:$Q$62,'Player Game Log'!$F$5:$F$62,$B10) -> 9 | M10: =L10/C10 -> 1.8 | N10: =SUMIFS('Player Game Log'!$R$5:$R$62,'Player Game Log'!$F$5:$F$62,$B10) -> 2 | O10: =N10/C10 -> 0.4 | P10: =SUMIFS('Player Game Log'!$S$5:$S$62,'Player Game Log'!$F$5:$F$62,$B10) -> 12 | Q10: =P10/C10 -> 2.4 | R10: =SUMIFS('Player Game Log'!$T$5:$T$62,'Player Game Log'!$F$5:$F$62,$B10) -> 2 | S10: =SUMIFS('Player Game Log'!$U$5:$U$62,'Player Game Log'!$F$5:$F$62,$B10) -> 7 | T10: =S10/C10 -> 1.4 | U10: =SUMIFS('Player Game Log'!$H$5:$H$62,'Player Game Log'!$F$5:$F$62,$B10) -> 15 | V10: =SUMIFS('Player Game Log'!$I$5:$I$62,'Player Game Log'!$F$5:$F$62,$B10) -> 33 | W10: =IF(V10=0,"",U10/V10) -> 0.45454545 | X10: =SUMIFS('Player Game Log'!$J$5:$J$62,'Player Game Log'!$F$5:$F$62,$B10) -> 9 | Y10: =SUMIFS('Player Game Log'!$K$5:$K$62,'Player Game Log'!$F$5:$F$62,$B10) -> 22 | Z10: =IF(Y10=0,"",X10/Y10) -> 0.40909091 | AA10: =SUMIFS('Player Game Log'!$L$5:$L$62,'Player Game Log'!$F$5:$F$62,$B10) -> 5 | AB10: =SUMIFS('Player Game Log'!$M$5:$M$62,'Player Game Log'!$F$5:$F$62,$B10) -> 6 | AC10: =IF(AB10=0,"",AA10/AB10) -> 0.83333333 | AD10: =IF(V10=0,"",(U10+0.5*X10)/V10) -> 0.59090909 | AE10: =IF(V10+AB10=0,"",G10/(2*(V10+0.44*AB10))) -> 0.61728395 | AF10: =IF(E10=0,"",G10/E10*40) -> 22.055138
A11: 34 | B11: Brayden Shorter | C11: =COUNTIFS('Player Game Log'!$F$5:$F$62,$B11) -> 5 | D11: =COUNTIFS('Player Game Log'!$F$5:$F$62,$B11,'Player Game Log'!$W$5:$W$62,"Yes") -> 2 | E11: =SUMIFS('Player Game Log'!$G$5:$G$62,'Player Game Log'!$F$5:$F$62,$B11) -> 69.97 | F11: =IFERROR(E11/COUNTIFS('Player Game Log'!$F$5:$F$62,$B11,'Player Game Log'!$G$5:$G$62,"<>"),"") -> 17.4925 | G11: =SUMIFS('Player Game Log'!$V$5:$V$62,'Player Game Log'!$F$5:$F$62,$B11) -> 44 | H11: =G11/C11 -> 8.8 | I11: =SUMIFS('Player Game Log'!$P$5:$P$62,'Player Game Log'!$F$5:$F$62,$B11) -> 12 | J11: =I11/C11 -> 2.4 | K11: =SUMIFS('Player Game Log'!$N$5:$N$62,'Player Game Log'!$F$5:$F$62,$B11) -> 5 | L11: =SUMIFS('Player Game Log'!$Q$5:$Q$62,'Player Game Log'!$F$5:$F$62,$B11) -> 9 | M11: =L11/C11 -> 1.8 | N11: =SUMIFS('Player Game Log'!$R$5:$R$62,'Player Game Log'!$F$5:$F$62,$B11) -> 4 | O11: =N11/C11 -> 0.8 | P11: =SUMIFS('Player Game Log'!$S$5:$S$62,'Player Game Log'!$F$5:$F$62,$B11) -> 8 | Q11: =P11/C11 -> 1.6 | R11: =SUMIFS('Player Game Log'!$T$5:$T$62,'Player Game Log'!$F$5:$F$62,$B11) -> 0 | S11: =SUMIFS('Player Game Log'!$U$5:$U$62,'Player Game Log'!$F$5:$F$62,$B11) -> 3 | T11: =S11/C11 -> 0.6 | U11: =SUMIFS('Player Game Log'!$H$5:$H$62,'Player Game Log'!$F$5:$F$62,$B11) -> 14 | V11: =SUMIFS('Player Game Log'!$I$5:$I$62,'Player Game Log'!$F$5:$F$62,$B11) -> 35 | W11: =IF(V11=0,"",U11/V11) -> 0.4 | X11: =SUMIFS('Player Game Log'!$J$5:$J$62,'Player Game Log'!$F$5:$F$62,$B11) -> 10 | Y11: =SUMIFS('Player Game Log'!$K$5:$K$62,'Player Game Log'!$F$5:$F$62,$B11) -> 29 | Z11: =IF(Y11=0,"",X11/Y11) -> 0.34482759 | AA11: =SUMIFS('Player Game Log'!$L$5:$L$62,'Player Game Log'!$F$5:$F$62,$B11) -> 6 | AB11: =SUMIFS('Player Game Log'!$M$5:$M$62,'Player Game Log'!$F$5:$F$62,$B11) -> 7 | AC11: =IF(AB11=0,"",AA11/AB11) -> 0.85714286 | AD11: =IF(V11=0,"",(U11+0.5*X11)/V11) -> 0.54285714 | AE11: =IF(V11+AB11=0,"",G11/(2*(V11+0.44*AB11))) -> 0.57773109 | AF11: =IF(E11=0,"",G11/E11*40) -> 25.153637
A12: 11 | B12: Brigham Rogers | C12: =COUNTIFS('Player Game Log'!$F$5:$F$62,$B12) -> 5 | D12: =COUNTIFS('Player Game Log'!$F$5:$F$62,$B12,'Player Game Log'!$W$5:$W$62,"Yes") -> 2 | E12: =SUMIFS('Player Game Log'!$G$5:$G$62,'Player Game Log'!$F$5:$F$62,$B12) -> 92.38 | F12: =IFERROR(E12/COUNTIFS('Player Game Log'!$F$5:$F$62,$B12,'Player Game Log'!$G$5:$G$62,"<>"),"") -> 23.095 | G12: =SUMIFS('Player Game Log'!$V$5:$V$62,'Player Game Log'!$F$5:$F$62,$B12) -> 38 | H12: =G12/C12 -> 7.6 | I12: =SUMIFS('Player Game Log'!$P$5:$P$62,'Player Game Log'!$F$5:$F$62,$B12) -> 33 | J12: =I12/C12 -> 6.6 | K12: =SUMIFS('Player Game Log'!$N$5:$N$62,'Player Game Log'!$F$5:$F$62,$B12) -> 15 | L12: =SUMIFS('Player Game Log'!$Q$5:$Q$62,'Player Game Log'!$F$5:$F$62,$B12) -> 15 | M12: =L12/C12 -> 3 | N12: =SUMIFS('Player Game Log'!$R$5:$R$62,'Player Game Log'!$F$5:$F$62,$B12) -> 7 | O12: =N12/C12 -> 1.4 | P12: =SUMIFS('Player Game Log'!$S$5:$S$62,'Player Game Log'!$F$5:$F$62,$B12) -> 8 | Q12: =P12/C12 -> 1.6 | R12: =SUMIFS('Player Game Log'!$T$5:$T$62,'Player Game Log'!$F$5:$F$62,$B12) -> 4 | S12: =SUMIFS('Player Game Log'!$U$5:$U$62,'Player Game Log'!$F$5:$F$62,$B12) -> 25 | T12: =S12/C12 -> 5 | U12: =SUMIFS('Player Game Log'!$H$5:$H$62,'Player Game Log'!$F$5:$F$62,$B12) -> 15 | V12: =SUMIFS('Player Game Log'!$I$5:$I$62,'Player Game Log'!$F$5:$F$62,$B12) -> 29 | W12: =IF(V12=0,"",U12/V12) -> 0.51724138 | X12: =SUMIFS('Player Game Log'!$J$5:$J$62,'Player Game Log'!$F$5:$F$62,$B12) -> 0 | Y12: =SUMIFS('Player Game Log'!$K$5:$K$62,'Player Game Log'!$F$5:$F$62,$B12) -> 0 | Z12: =IF(Y12=0,"",X12/Y12) | AA12: =SUMIFS('Player Game Log'!$L$5:$L$62,'Player Game Log'!$F$5:$F$62,$B12) -> 8 | AB12: =SUMIFS('Player Game Log'!$M$5:$M$62,'Player Game Log'!$F$5:$F$62,$B12) -> 14 | AC12: =IF(AB12=0,"",AA12/AB12) -> 0.57142857 | AD12: =IF(V12=0,"",(U12+0.5*X12)/V12) -> 0.51724138 | AE12: =IF(V12+AB12=0,"",G12/(2*(V12+0.44*AB12))) -> 0.5403868 | AF12: =IF(E12=0,"",G12/E12*40) -> 16.453778
A13: 8 | B13: Talis Soulhac | C13: =COUNTIFS('Player Game Log'!$F$5:$F$62,$B13) -> 2 | D13: =COUNTIFS('Player Game Log'!$F$5:$F$62,$B13,'Player Game Log'!$W$5:$W$62,"Yes") -> 2 | E13: =SUMIFS('Player Game Log'!$G$5:$G$62,'Player Game Log'!$F$5:$F$62,$B13) -> 38.4 | F13: =IFERROR(E13/COUNTIFS('Player Game Log'!$F$5:$F$62,$B13,'Player Game Log'!$G$5:$G$62,"<>"),"") -> 19.2 | G13: =SUMIFS('Player Game Log'!$V$5:$V$62,'Player Game Log'!$F$5:$F$62,$B13) -> 14 | H13: =G13/C13 -> 7 | I13: =SUMIFS('Player Game Log'!$P$5:$P$62,'Player Game Log'!$F$5:$F$62,$B13) -> 8 | J13: =I13/C13 -> 4 | K13: =SUMIFS('Player Game Log'!$N$5:$N$62,'Player Game Log'!$F$5:$F$62,$B13) -> 1 | L13: =SUMIFS('Player Game Log'!$Q$5:$Q$62,'Player Game Log'!$F$5:$F$62,$B13) -> 1 | M13: =L13/C13 -> 0.5 | N13: =SUMIFS('Player Game Log'!$R$5:$R$62,'Player Game Log'!$F$5:$F$62,$B13) -> 2 | O13: =N13/C13 -> 1 | P13: =SUMIFS('Player Game Log'!$S$5:$S$62,'Player Game Log'!$F$5:$F$62,$B13) -> 0 | Q13: =P13/C13 -> 0 | R13: =SUMIFS('Player Game Log'!$T$5:$T$62,'Player Game Log'!$F$5:$F$62,$B13) -> 0 | S13: =SUMIFS('Player Game Log'!$U$5:$U$62,'Player Game Log'!$F$5:$F$62,$B13) -> 4 | T13: =S13/C13 -> 2 | U13: =SUMIFS('Player Game Log'!$H$5:$H$62,'Player Game Log'!$F$5:$F$62,$B13) -> 3 | V13: =SUMIFS('Player Game Log'!$I$5:$I$62,'Player Game Log'!$F$5:$F$62,$B13) -> 8 | W13: =IF(V13=0,"",U13/V13) -> 0.375 | X13: =SUMIFS('Player Game Log'!$J$5:$J$62,'Player Game Log'!$F$5:$F$62,$B13) -> 1 | Y13: =SUMIFS('Player Game Log'!$K$5:$K$62,'Player Game Log'!$F$5:$F$62,$B13) -> 4 | Z13: =IF(Y13=0,"",X13/Y13) -> 0.25 | AA13: =SUMIFS('Player Game Log'!$L$5:$L$62,'Player Game Log'!$F$5:$F$62,$B13) -> 7 | AB13: =SUMIFS('Player Game Log'!$M$5:$M$62,'Player Game Log'!$F$5:$F$62,$B13) -> 9 | AC13: =IF(AB13=0,"",AA13/AB13) -> 0.77777778 | AD13: =IF(V13=0,"",(U13+0.5*X13)/V13) -> 0.4375 | AE13: =IF(V13+AB13=0,"",G13/(2*(V13+0.44*AB13))) -> 0.58528428 | AF13: =IF(E13=0,"",G13/E13*40) -> 14.583333
A14: 7 | B14: Ben Shtolzberg | C14: =COUNTIFS('Player Game Log'!$F$5:$F$62,$B14) -> 5 | D14: =COUNTIFS('Player Game Log'!$F$5:$F$62,$B14,'Player Game Log'!$W$5:$W$62,"Yes") -> 0 | E14: =SUMIFS('Player Game Log'!$G$5:$G$62,'Player Game Log'!$F$5:$F$62,$B14) -> 59.98 | F14: =IFERROR(E14/COUNTIFS('Player Game Log'!$F$5:$F$62,$B14,'Player Game Log'!$G$5:$G$62,"<>"),"") -> 14.995 | G14: =SUMIFS('Player Game Log'!$V$5:$V$62,'Player Game Log'!$F$5:$F$62,$B14) -> 31 | H14: =G14/C14 -> 6.2 | I14: =SUMIFS('Player Game Log'!$P$5:$P$62,'Player Game Log'!$F$5:$F$62,$B14) -> 13 | J14: =I14/C14 -> 2.6 | K14: =SUMIFS('Player Game Log'!$N$5:$N$62,'Player Game Log'!$F$5:$F$62,$B14) -> 6 | L14: =SUMIFS('Player Game Log'!$Q$5:$Q$62,'Player Game Log'!$F$5:$F$62,$B14) -> 11 | M14: =L14/C14 -> 2.2 | N14: =SUMIFS('Player Game Log'!$R$5:$R$62,'Player Game Log'!$F$5:$F$62,$B14) -> 4 | O14: =N14/C14 -> 0.8 | P14: =SUMIFS('Player Game Log'!$S$5:$S$62,'Player Game Log'!$F$5:$F$62,$B14) -> 6 | Q14: =P14/C14 -> 1.2 | R14: =SUMIFS('Player Game Log'!$T$5:$T$62,'Player Game Log'!$F$5:$F$62,$B14) -> 1 | S14: =SUMIFS('Player Game Log'!$U$5:$U$62,'Player Game Log'!$F$5:$F$62,$B14) -> 14 | T14: =S14/C14 -> 2.8 | U14: =SUMIFS('Player Game Log'!$H$5:$H$62,'Player Game Log'!$F$5:$F$62,$B14) -> 12 | V14: =SUMIFS('Player Game Log'!$I$5:$I$62,'Player Game Log'!$F$5:$F$62,$B14) -> 23 | W14: =IF(V14=0,"",U14/V14) -> 0.52173913 | X14: =SUMIFS('Player Game Log'!$J$5:$J$62,'Player Game Log'!$F$5:$F$62,$B14) -> 1 | Y14: =SUMIFS('Player Game Log'!$K$5:$K$62,'Player Game Log'!$F$5:$F$62,$B14) -> 6 | Z14: =IF(Y14=0,"",X14/Y14) -> 0.16666667 | AA14: =SUMIFS('Player Game Log'!$L$5:$L$62,'Player Game Log'!$F$5:$F$62,$B14) -> 6 | AB14: =SUMIFS('Player Game Log'!$M$5:$M$62,'Player Game Log'!$F$5:$F$62,$B14) -> 7 | AC14: =IF(AB14=0,"",AA14/AB14) -> 0.85714286 | AD14: =IF(V14=0,"",(U14+0.5*X14)/V14) -> 0.54347826 | AE14: =IF(V14+AB14=0,"",G14/(2*(V14+0.44*AB14))) -> 0.59432515 | AF14: =IF(E14=0,"",G14/E14*40) -> 20.673558
A15: 4 | B15: Mark Padjen | C15: =COUNTIFS('Player Game Log'!$F$5:$F$62,$B15) -> 4 | D15: =COUNTIFS('Player Game Log'!$F$5:$F$62,$B15,'Player Game Log'!$W$5:$W$62,"Yes") -> 0 | E15: =SUMIFS('Player Game Log'!$G$5:$G$62,'Player Game Log'!$F$5:$F$62,$B15) -> 38.82 | F15: =IFERROR(E15/COUNTIFS('Player Game Log'!$F$5:$F$62,$B15,'Player Game Log'!$G$5:$G$62,"<>"),"") -> 12.94 | G15: =SUMIFS('Player Game Log'!$V$5:$V$62,'Player Game Log'!$F$5:$F$62,$B15) -> 17 | H15: =G15/C15 -> 4.25 | I15: =SUMIFS('Player Game Log'!$P$5:$P$62,'Player Game Log'!$F$5:$F$62,$B15) -> 12 | J15: =I15/C15 -> 3 | K15: =SUMIFS('Player Game Log'!$N$5:$N$62,'Player Game Log'!$F$5:$F$62,$B15) -> 3 | L15: =SUMIFS('Player Game Log'!$Q$5:$Q$62,'Player Game Log'!$F$5:$F$62,$B15) -> 7 | M15: =L15/C15 -> 1.75 | N15: =SUMIFS('Player Game Log'!$R$5:$R$62,'Player Game Log'!$F$5:$F$62,$B15) -> 3 | O15: =N15/C15 -> 0.75 | P15: =SUMIFS('Player Game Log'!$S$5:$S$62,'Player Game Log'!$F$5:$F$62,$B15) -> 6 | Q15: =P15/C15 -> 1.5 | R15: =SUMIFS('Player Game Log'!$T$5:$T$62,'Player Game Log'!$F$5:$F$62,$B15) -> 0 | S15: =SUMIFS('Player Game Log'!$U$5:$U$62,'Player Game Log'!$F$5:$F$62,$B15) -> 4 | T15: =S15/C15 -> 1 | U15: =SUMIFS('Player Game Log'!$H$5:$H$62,'Player Game Log'!$F$5:$F$62,$B15) -> 5 | V15: =SUMIFS('Player Game Log'!$I$5:$I$62,'Player Game Log'!$F$5:$F$62,$B15) -> 15 | W15: =IF(V15=0,"",U15/V15) -> 0.33333333 | X15: =SUMIFS('Player Game Log'!$J$5:$J$62,'Player Game Log'!$F$5:$F$62,$B15) -> 3 | Y15: =SUMIFS('Player Game Log'!$K$5:$K$62,'Player Game Log'!$F$5:$F$62,$B15) -> 11 | Z15: =IF(Y15=0,"",X15/Y15) -> 0.27272727 | AA15: =SUMIFS('Player Game Log'!$L$5:$L$62,'Player Game Log'!$F$5:$F$62,$B15) -> 4 | AB15: =SUMIFS('Player Game Log'!$M$5:$M$62,'Player Game Log'!$F$5:$F$62,$B15) -> 4 | AC15: =IF(AB15=0,"",AA15/AB15) -> 1 | AD15: =IF(V15=0,"",(U15+0.5*X15)/V15) -> 0.43333333 | AE15: =IF(V15+AB15=0,"",G15/(2*(V15+0.44*AB15))) -> 0.5071599 | AF15: =IF(E15=0,"",G15/E15*40) -> 17.516744
A16: 23 | B16: Shon Tupuola | C16: =COUNTIFS('Player Game Log'!$F$5:$F$62,$B16) -> 5 | D16: =COUNTIFS('Player Game Log'!$F$5:$F$62,$B16,'Player Game Log'!$W$5:$W$62,"Yes") -> 1 | E16: =SUMIFS('Player Game Log'!$G$5:$G$62,'Player Game Log'!$F$5:$F$62,$B16) -> 58.35 | F16: =IFERROR(E16/COUNTIFS('Player Game Log'!$F$5:$F$62,$B16,'Player Game Log'!$G$5:$G$62,"<>"),"") -> 14.5875 | G16: =SUMIFS('Player Game Log'!$V$5:$V$62,'Player Game Log'!$F$5:$F$62,$B16) -> 19 | H16: =G16/C16 -> 3.8 | I16: =SUMIFS('Player Game Log'!$P$5:$P$62,'Player Game Log'!$F$5:$F$62,$B16) -> 22 | J16: =I16/C16 -> 4.4 | K16: =SUMIFS('Player Game Log'!$N$5:$N$62,'Player Game Log'!$F$5:$F$62,$B16) -> 6 | L16: =SUMIFS('Player Game Log'!$Q$5:$Q$62,'Player Game Log'!$F$5:$F$62,$B16) -> 3 | M16: =L16/C16 -> 0.6 | N16: =SUMIFS('Player Game Log'!$R$5:$R$62,'Player Game Log'!$F$5:$F$62,$B16) -> 0 | O16: =N16/C16 -> 0 | P16: =SUMIFS('Player Game Log'!$S$5:$S$62,'Player Game Log'!$F$5:$F$62,$B16) -> 2 | Q16: =P16/C16 -> 0.4 | R16: =SUMIFS('Player Game Log'!$T$5:$T$62,'Player Game Log'!$F$5:$F$62,$B16) -> 1 | S16: =SUMIFS('Player Game Log'!$U$5:$U$62,'Player Game Log'!$F$5:$F$62,$B16) -> 4 | T16: =S16/C16 -> 0.8 | U16: =SUMIFS('Player Game Log'!$H$5:$H$62,'Player Game Log'!$F$5:$F$62,$B16) -> 8 | V16: =SUMIFS('Player Game Log'!$I$5:$I$62,'Player Game Log'!$F$5:$F$62,$B16) -> 19 | W16: =IF(V16=0,"",U16/V16) -> 0.42105263 | X16: =SUMIFS('Player Game Log'!$J$5:$J$62,'Player Game Log'!$F$5:$F$62,$B16) -> 0 | Y16: =SUMIFS('Player Game Log'!$K$5:$K$62,'Player Game Log'!$F$5:$F$62,$B16) -> 1 | Z16: =IF(Y16=0,"",X16/Y16) -> 0 | AA16: =SUMIFS('Player Game Log'!$L$5:$L$62,'Player Game Log'!$F$5:$F$62,$B16) -> 3 | AB16: =SUMIFS('Player Game Log'!$M$5:$M$62,'Player Game Log'!$F$5:$F$62,$B16) -> 8 | AC16: =IF(AB16=0,"",AA16/AB16) -> 0.375 | AD16: =IF(V16=0,"",(U16+0.5*X16)/V16) -> 0.42105263 | AE16: =IF(V16+AB16=0,"",G16/(2*(V16+0.44*AB16))) -> 0.42184725 | AF16: =IF(E16=0,"",G16/E16*40) -> 13.02485
... A18: 25 | B18: Dillon Butler | C18: =COUNTIFS('Player Game Log'!$F$5:$F$62,$B18) -> 3 | D18: =COUNTIFS('Player Game Log'!$F$5:$F$62,$B18,'Player Game Log'!$W$5:$W$62,"Yes") -> 0 | E18: =SUMIFS('Player Game Log'!$G$5:$G$62,'Player Game Log'!$F$5:$F$62,$B18) -> 4.03 | F18: =IFERROR(E18/COUNTIFS('Player Game Log'!$F$5:$F$62,$B18,'Player Game Log'!$G$5:$G$62,"<>"),"") -> 1.3433333 | G18: =SUMIFS('Player Game Log'!$V$5:$V$62,'Player Game Log'!$F$5:$F$62,$B18) -> 0 | H18: =G18/C18 -> 0 | I18: =SUMIFS('Player Game Log'!$P$5:$P$62,'Player Game Log'!$F$5:$F$62,$B18) -> 0 | J18: =I18/C18 -> 0 | K18: =SUMIFS('Player Game Log'!$N$5:$N$62,'Player Game Log'!$F$5:$F$62,$B18) -> 0 | L18: =SUMIFS('Player Game Log'!$Q$5:$Q$62,'Player Game Log'!$F$5:$F$62,$B18) -> 0 | M18: =L18/C18 -> 0 | N18: =SUMIFS('Player Game Log'!$R$5:$R$62,'Player Game Log'!$F$5:$F$62,$B18) -> 0 | O18: =N18/C18 -> 0 | P18: =SUMIFS('Player Game Log'!$S$5:$S$62,'Player Game Log'!$F$5:$F$62,$B18) -> 0 | Q18: =P18/C18 -> 0 | R18: =SUMIFS('Player Game Log'!$T$5:$T$62,'Player Game Log'!$F$5:$F$62,$B18) -> 0 | S18: =SUMIFS('Player Game Log'!$U$5:$U$62,'Player Game Log'!$F$5:$F$62,$B18) -> 1 | T18: =S18/C18 -> 0.33333333 | U18: =SUMIFS('Player Game Log'!$H$5:$H$62,'Player Game Log'!$F$5:$F$62,$B18) -> 0 | V18: =SUMIFS('Player Game Log'!$I$5:$I$62,'Player Game Log'!$F$5:$F$62,$B18) -> 2 | W18: =IF(V18=0,"",U18/V18) -> 0 | X18: =SUMIFS('Player Game Log'!$J$5:$J$62,'Player Game Log'!$F$5:$F$62,$B18) -> 0 | Y18: =SUMIFS('Player Game Log'!$K$5:$K$62,'Player Game Log'!$F$5:$F$62,$B18) -> 0 | Z18: =IF(Y18=0,"",X18/Y18) | AA18: =SUMIFS('Player Game Log'!$L$5:$L$62,'Player Game Log'!$F$5:$F$62,$B18) -> 0 | AB18: =SUMIFS('Player Game Log'!$M$5:$M$62,'Player Game Log'!$F$5:$F$62,$B18) -> 0 | AC18: =IF(AB18=0,"",AA18/AB18) | AD18: =IF(V18=0,"",(U18+0.5*X18)/V18) -> 0 | AE18: =IF(V18+AB18=0,"",G18/(2*(V18+0.44*AB18))) -> 0 | AF18: =IF(E18=0,"",G18/E18*40) -> 0
B19: Team (players) | E19: =SUM(E5:E18) -> 799.99 | G19: =SUM(G5:G18) -> 479 | I19: =SUM(I5:I18) -> 190 | K19: =SUM(K5:K18) -> 62 | L19: =SUM(L5:L18) -> 102 | N19: =SUM(N5:N18) -> 69 | P19: =SUM(P5:P18) -> 77 | R19: =SUM(R5:R18) -> 13 | S19: =SUM(S5:S18) -> 116 | U19: =SUM(U5:U18) -> 172 | V19: =SUM(V5:V18) -> 362 | W19: =U19/V19 -> 0.47513812 | X19: =SUM(X5:X18) -> 51 | Y19: =SUM(Y5:Y18) -> 162 | Z19: =X19/Y19 -> 0.31481481 | AA19: =SUM(AA5:AA18) -> 84 | AB19: =SUM(AB5:AB18) -> 114 | AC19: =AA19/AB19 -> 0.73684211 | AD19: =(U19+0.5*X19)/V19 -> 0.54558011
A21: Team rebounds and team turnovers are credited to no player, so the player sum can be a few rebounds/turnovers lower than the team total. GS counts only games whose box score lists starters (France, Wichita State, UIW).
A23: Shaded cells = weaknesses flagged in the scouting notes.

Sheet October Only
A1: Murray State: player stats, October games only (at Wichita State, vs UIW)
A2: Every number below is a formula over the Player Game Log tab. Per-game = total ÷ GP. MPG uses only games with minutes recorded.
A4: # | B4: Player | C4: GP | D4: GS | E4: MIN | F4: MPG | G4: PTS | H4: PPG | I4: REB | J4: RPG | K4: OREB | L4: AST | M4: APG | N4: TO | O4: TOPG | P4: STL | Q4: SPG | R4: BLK | S4: PF | T4: PF/G | U4: FGM | V4: FGA | W4: FG% | X4: 3PM | Y4: 3PA | Z4: 3P% | AA4: FTM | AB4: FTA | AC4: FT% | AD4: eFG% | AE4: TS% | AF4: PTS/40
A5: 77 | B5: Roman Domon | C5: =COUNTIFS('Player Game Log'!$F$5:$F$62,$B5,'Player Game Log'!$C$5:$C$62,"October") -> 2 | D5: =COUNTIFS('Player Game Log'!$F$5:$F$62,$B5,'Player Game Log'!$W$5:$W$62,"Yes",'Player Game Log'!$C$5:$C$62,"October") -> 2 | E5: =SUMIFS('Player Game Log'!$G$5:$G$62,'Player Game Log'!$F$5:$F$62,$B5,'Player Game Log'!$C$5:$C$62,"October") -> 58.33 | F5: =IFERROR(E5/COUNTIFS('Player Game Log'!$F$5:$F$62,$B5,'Player Game Log'!$G$5:$G$62,"<>",'Player Game Log'!$C$5:$C$62,"October"),"") -> 29.165 | G5: =SUMIFS('Player Game Log'!$V$5:$V$62,'Player Game Log'!$F$5:$F$62,$B5,'Player Game Log'!$C$5:$C$62,"October") -> 47 | H5: =G5/C5 -> 23.5 | I5: =SUMIFS('Player Game Log'!$P$5:$P$62,'Player Game Log'!$F$5:$F$62,$B5,'Player Game Log'!$C$5:$C$62,"October") -> 5 | J5: =I5/C5 -> 2.5 | K5: =SUMIFS('Player Game Log'!$N$5:$N$62,'Player Game Log'!$F$5:$F$62,$B5,'Player Game Log'!$C$5:$C$62,"October") -> 0 | L5: =SUMIFS('Player Game Log'!$Q$5:$Q$62,'Player Game Log'!$F$5:$F$62,$B5,'Player Game Log'!$C$5:$C$62,"October") -> 7 | M5: =L5/C5 -> 3.5 | N5: =SUMIFS('Player Game Log'!$R$5:$R$62,'Player Game Log'!$F$5:$F$62,$B5,'Player Game Log'!$C$5:$C$62,"October") -> 7 | O5: =N5/C5 -> 3.5 | P5: =SUMIFS('Player Game Log'!$S$5:$S$62,'Player Game Log'!$F$5:$F$62,$B5,'Player Game Log'!$C$5:$C$62,"October") -> 6 | Q5: =P5/C5 -> 3 | R5: =SUMIFS('Player Game Log'!$T$5:$T$62,'Player Game Log'!$F$5:$F$62,$B5,'Player Game Log'!$C$5:$C$62,"October") -> 1 | S5: =SUMIFS('Player Game Log'!$U$5:$U$62,'Player Game Log'!$F$5:$F$62,$B5,'Player Game Log'!$C$5:$C$62,"October") -> 6 | T5: =S5/C5 -> 3 | U5: =SUMIFS('Player Game Log'!$H$5:$H$62,'Player Game Log'!$F$5:$F$62,$B5,'Player Game Log'!$C$5:$C$62,"October") -> 15 | V5: =SUMIFS('Player Game Log'!$I$5:$I$62,'Player Game Log'!$F$5:$F$62,$B5,'Player Game Log'!$C$5:$C$62,"October") -> 27 | W5: =IF(V5=0,"",U5/V5) -> 0.55555556 | X5: =SUMIFS('Player Game Log'!$J$5:$J$62,'Player Game Log'!$F$5:$F$62,$B5,'Player Game Log'!$C$5:$C$62,"October") -> 3 | Y5: =SUMIFS('Player Game Log'!$K$5:$K$62,'Player Game Log'!$F$5:$F$62,$B5,'Player Game Log'!$C$5:$C$62,"October") -> 10 | Z5: =IF(Y5=0,"",X5/Y5) -> 0.3 | AA5: =SUMIFS('Player Game Log'!$L$5:$L$62,'Player Game Log'!$F$5:$F$62,$B5,'Player Game Log'!$C$5:$C$62,"October") -> 14 | AB5: =SUMIFS('Player Game Log'!$M$5:$M$62,'Player Game Log'!$F$5:$F$62,$B5,'Player Game Log'!$C$5:$C$62,"October") -> 16 | AC5: =IF(AB5=0,"",AA5/AB5) -> 0.875 | AD5: =IF(V5=0,"",(U5+0.5*X5)/V5) -> 0.61111111 | AE5: =IF(V5+AB5=0,"",G5/(2*(V5+0.44*AB5))) -> 0.69036428 | AF5: =IF(E5=0,"",G5/E5*40) -> 32.230413
A6: 6 | B6: Christian Jones | C6: =COUNTIFS('Player Game Log'!$F$5:$F$62,$B6,'Player Game Log'!$C$5:$C$62,"October") -> 2 | D6: =COUNTIFS('Player Game Log'!$F$5:$F$62,$B6,'Player Game Log'!$W$5:$W$62,"Yes",'Player Game Log'!$C$5:$C$62,"October") -> 0 | E6: =SUMIFS('Player Game Log'!$G$5:$G$62,'Player Game Log'!$F$5:$F$62,$B6,'Player Game Log'!$C$5:$C$62,"October") -> 39.87 | F6: =IFERROR(E6/COUNTIFS('Player Game Log'!$F$5:$F$62,$B6,'Player Game Log'!$G$5:$G$62,"<>",'Player Game Log'!$C$5:$C$62,"October"),"") -> 19.935 | G6: =SUMIFS('Player Game Log'!$V$5:$V$62,'Player Game Log'!$F$5:$F$62,$B6,'Player Game Log'!$C$5:$C$62,"October") -> 22 | H6: =G6/C6 -> 11 | I6: =SUMIFS('Player Game Log'!$P$5:$P$62,'Player Game Log'!$F$5:$F$62,$B6,'Player Game Log'!$C$5:$C$62,"October") -> 7 | J6: =I6/C6 -> 3.5 | K6: =SUMIFS('Player Game Log'!$N$5:$N$62,'Player Game Log'!$F$5:$F$62,$B6,'Player Game Log'!$C$5:$C$62,"October") -> 2 | L6: =SUMIFS('Player Game Log'!$Q$5:$Q$62,'Player Game Log'!$F$5:$F$62,$B6,'Player Game Log'!$C$5:$C$62,"October") -> 7 | M6: =L6/C6 -> 3.5 | N6: =SUMIFS('Player Game Log'!$R$5:$R$62,'Player Game Log'!$F$5:$F$62,$B6,'Player Game Log'!$C$5:$C$62,"October") -> 4 | O6: =N6/C6 -> 2 | P6: =SUMIFS('Player Game Log'!$S$5:$S$62,'Player Game Log'!$F$5:$F$62,$B6,'Player Game Log'!$C$5:$C$62,"October") -> 3 | Q6: =P6/C6 -> 1.5 | R6: =SUMIFS('Player Game Log'!$T$5:$T$62,'Player Game Log'!$F$5:$F$62,$B6,'Player Game Log'!$C$5:$C$62,"October") -> 0 | S6: =SUMIFS('Player Game Log'!$U$5:$U$62,'Player Game Log'!$F$5:$F$62,$B6,'Player Game Log'!$C$5:$C$62,"October") -> 4 | T6: =S6/C6 -> 2 | U6: =SUMIFS('Player Game Log'!$H$5:$H$62,'Player Game Log'!$F$5:$F$62,$B6,'Player Game Log'!$C$5:$C$62,"October") -> 8 | V6: =SUMIFS('Player Game Log'!$I$5:$I$62,'Player Game Log'!$F$5:$F$62,$B6,'Player Game Log'!$C$5:$C$62,"October") -> 19 | W6: =IF(V6=0,"",U6/V6) -> 0.42105263 | X6: =SUMIFS('Player Game Log'!$J$5:$J$62,'Player Game Log'!$F$5:$F$62,$B6,'Player Game Log'!$C$5:$C$62,"October") -> 2 | Y6: =SUMIFS('Player Game Log'!$K$5:$K$62,'Player Game Log'!$F$5:$F$62,$B6,'Player Game Log'!$C$5:$C$62,"October") -> 9 | Z6: =IF(Y6=0,"",X6/Y6) -> 0.22222222 | AA6: =SUMIFS('Player Game Log'!$L$5:$L$62,'Player Game Log'!$F$5:$F$62,$B6,'Player Game Log'!$C$5:$C$62,"October") -> 4 | AB6: =SUMIFS('Player Game Log'!$M$5:$M$62,'Player Game Log'!$F$5:$F$62,$B6,'Player Game Log'!$C$5:$C$62,"October") -> 4 | AC6: =IF(AB6=0,"",AA6/AB6) -> 1 | AD6: =IF(V6=0,"",(U6+0.5*X6)/V6) -> 0.47368421 | AE6: =IF(V6+AB6=0,"",G6/(2*(V6+0.44*AB6))) -> 0.52986513 | AF6: =IF(E6=0,"",G6/E6*40) -> 22.071733
A7: 34 | B7: Brayden Shorter | C7: =COUNTIFS('Player Game Log'!$F$5:$F$62,$B7,'Player Game Log'!$C$5:$C$62,"October") -> 2 | D7: =COUNTIFS('Player Game Log'!$F$5:$F$62,$B7,'Player Game Log'!$W$5:$W$62,"Yes",'Player Game Log'!$C$5:$C$62,"October") -> 2 | E7: =SUMIFS('Player Game Log'!$G$5:$G$62,'Player Game Log'!$F$5:$F$62,$B7,'Player Game Log'!$C$5:$C$62,"October") -> 35.22 | F7: =IFERROR(E7/COUNTIFS('Player Game Log'!$F$5:$F$62,$B7,'Player Game Log'!$G$5:$G$62,"<>",'Player Game Log'!$C$5:$C$62,"October"),"") -> 17.61 | G7: =SUMIFS('Player Game Log'!$V$5:$V$62,'Player Game Log'!$F$5:$F$62,$B7,'Player Game Log'!$C$5:$C$62,"October") -> 21 | H7: =G7/C7 -> 10.5 | I7: =SUMIFS('Player Game Log'!$P$5:$P$62,'Player Game Log'!$F$5:$F$62,$B7,'Player Game Log'!$C$5:$C$62,"October") -> 5 | J7: =I7/C7 -> 2.5 | K7: =SUMIFS('Player Game Log'!$N$5:$N$62,'Player Game Log'!$F$5:$F$62,$B7,'Player Game Log'!$C$5:$C$62,"October") -> 1 | L7: =SUMIFS('Player Game Log'!$Q$5:$Q$62,'Player Game Log'!$F$5:$F$62,$B7,'Player Game Log'!$C$5:$C$62,"October") -> 1 | M7: =L7/C7 -> 0.5 | N7: =SUMIFS('Player Game Log'!$R$5:$R$62,'Player Game Log'!$F$5:$F$62,$B7,'Player Game Log'!$C$5:$C$62,"October") -> 2 | O7: =N7/C7 -> 1 | P7: =SUMIFS('Player Game Log'!$S$5:$S$62,'Player Game Log'!$F$5:$F$62,$B7,'Player Game Log'!$C$5:$C$62,"October") -> 2 | Q7: =P7/C7 -> 1 | R7: =SUMIFS('Player Game Log'!$T$5:$T$62,'Player Game Log'!$F$5:$F$62,$B7,'Player Game Log'!$C$5:$C$62,"October") -> 0 | S7: =SUMIFS('Player Game Log'!$U$5:$U$62,'Player Game Log'!$F$5:$F$62,$B7,'Player Game Log'!$C$5:$C$62,"October") -> 1 | T7: =S7/C7 -> 0.5 | U7: =SUMIFS('Player Game Log'!$H$5:$H$62,'Player Game Log'!$F$5:$F$62,$B7,'Player Game Log'!$C$5:$C$62,"October") -> 6 | V7: =SUMIFS('Player Game Log'!$I$5:$I$62,'Player Game Log'!$F$5:$F$62,$B7,'Player Game Log'!$C$5:$C$62,"October") -> 11 | W7: =IF(V7=0,"",U7/V7) -> 0.54545455 | X7: =SUMIFS('Player Game Log'!$J$5:$J$62,'Player Game Log'!$F$5:$F$62,$B7,'Player Game Log'!$C$5:$C$62,"October") -> 5 | Y7: =SUMIFS('Player Game Log'!$K$5:$K$62,'Player Game Log'!$F$5:$F$62,$B7,'Player Game Log'!$C$5:$C$62,"October") -> 10 | Z7: =IF(Y7=0,"",X7/Y7) -> 0.5 | AA7: =SUMIFS('Player Game Log'!$L$5:$L$62,'Player Game Log'!$F$5:$F$62,$B7,'Player Game Log'!$C$5:$C$62,"October") -> 4 | AB7: =SUMIFS('Player Game Log'!$M$5:$M$62,'Player Game Log'!$F$5:$F$62,$B7,'Player Game Log'!$C$5:$C$62,"October") -> 5 | AC7: =IF(AB7=0,"",AA7/AB7) -> 0.8 | AD7: =IF(V7=0,"",(U7+0.5*X7)/V7) -> 0.77272727 | AE7: =IF(V7+AB7=0,"",G7/(2*(V7+0.44*AB7))) -> 0.79545455 | AF7: =IF(E7=0,"",G7/E7*40) -> 23.850085
A8: 14 | B8: Lachlan Crate | C8: =COUNTIFS('Player Game Log'!$F$5:$F$62,$B8,'Player Game Log'!$C$5:$C$62,"October") -> 2 | D8: =COUNTIFS('Player Game Log'!$F$5:$F$62,$B8,'Player Game Log'!$W$5:$W$62,"Yes",'Player Game Log'!$C$5:$C$62,"October") -> 2 | E8: =SUMIFS('Player Game Log'!$G$5:$G$62,'Player Game Log'!$F$5:$F$62,$B8,'Player Game Log'!$C$5:$C$62,"October") -> 44.58 | F8: =IFERROR(E8/COUNTIFS('Player Game Log'!$F$5:$F$62,$B8,'Player Game Log'!$G$5:$G$62,"<>",'Player Game Log'!$C$5:$C$62,"October"),"") -> 22.29 | G8: =SUMIFS('Player Game Log'!$V$5:$V$62,'Player Game Log'!$F$5:$F$62,$B8,'Player Game Log'!$C$5:$C$62,"October") -> 21 | H8: =G8/C8 -> 10.5 | I8: =SUMIFS('Player Game Log'!$P$5:$P$62,'Player Game Log'!$F$5:$F$62,$B8,'Player Game Log'!$C$5:$C$62,"October") -> 6 | J8: =I8/C8 -> 3 | K8: =SUMIFS('Player Game Log'!$N$5:$N$62,'Player Game Log'!$F$5:$F$62,$B8,'Player Game Log'!$C$5:$C$62,"October") -> 4 | L8: =SUMIFS('Player Game Log'!$Q$5:$Q$62,'Player Game Log'!$F$5:$F$62,$B8,'Player Game Log'!$C$5:$C$62,"October") -> 1 | M8: =L8/C8 -> 0.5 | N8: =SUMIFS('Player Game Log'!$R$5:$R$62,'Player Game Log'!$F$5:$F$62,$B8,'Player Game Log'!$C$5:$C$62,"October") -> 1 | O8: =N8/C8 -> 0.5 | P8: =SUMIFS('Player Game Log'!$S$5:$S$62,'Player Game Log'!$F$5:$F$62,$B8,'Player Game Log'!$C$5:$C$62,"October") -> 0 | Q8: =P8/C8 -> 0 | R8: =SUMIFS('Player Game Log'!$T$5:$T$62,'Player Game Log'!$F$5:$F$62,$B8,'Player Game Log'!$C$5:$C$62,"October") -> 0 | S8: =SUMIFS('Player Game Log'!$U$5:$U$62,'Player Game Log'!$F$5:$F$62,$B8,'Player Game Log'!$C$5:$C$62,"October") -> 6 | T8: =S8/C8 -> 3 | U8: =SUMIFS('Player Game Log'!$H$5:$H$62,'Player Game Log'!$F$5:$F$62,$B8,'Player Game Log'!$C$5:$C$62,"October") -> 8 | V8: =SUMIFS('Player Game Log'!$I$5:$I$62,'Player Game Log'!$F$5:$F$62,$B8,'Player Game Log'!$C$5:$C$62,"October") -> 11 | W8: =IF(V8=0,"",U8/V8) -> 0.72727273 | X8: =SUMIFS('Player Game Log'!$J$5:$J$62,'Player Game Log'!$F$5:$F$62,$B8,'Player Game Log'!$C$5:$C$62,"October") -> 1 | Y8: =SUMIFS('Player Game Log'!$K$5:$K$62,'Player Game Log'!$F$5:$F$62,$B8,'Player Game Log'!$C$5:$C$62,"October") -> 2 | Z8: =IF(Y8=0,"",X8/Y8) -> 0.5 | AA8: =SUMIFS('Player Game Log'!$L$5:$L$62,'Player Game Log'!$F$5:$F$62,$B8,'Player Game Log'!$C$5:$C$62,"October") -> 4 | AB8: =SUMIFS('Player Game Log'!$M$5:$M$62,'Player Game Log'!$F$5:$F$62,$B8,'Player Game Log'!$C$5:$C$62,"October") -> 6 | AC8: =IF(AB8=0,"",AA8/AB8) -> 0.66666667 | AD8: =IF(V8=0,"",(U8+0.5*X8)/V8) -> 0.77272727 | AE8: =IF(V8+AB8=0,"",G8/(2*(V8+0.44*AB8))) -> 0.76979472 | AF8: =IF(E8=0,"",G8/E8*40) -> 18.84253
A9: 16 | B9: Jonas Boulefaa | C9: =COUNTIFS('Player Game Log'!$F$5:$F$62,$B9,'Player Game Log'!$C$5:$C$62,"October") -> 1 | D9: =COUNTIFS('Player Game Log'!$F$5:$F$62,$B9,'Player Game Log'!$W$5:$W$62,"Yes",'Player Game Log'!$C$5:$C$62,"October") -> 0 | E9: =SUMIFS('Player Game Log'!$G$5:$G$62,'Player Game Log'!$F$5:$F$62,$B9,'Player Game Log'!$C$5:$C$62,"October") -> 9.27 | F9: =IFERROR(E9/COUNTIFS('Player Game Log'!$F$5:$F$62,$B9,'Player Game Log'!$G$5:$G$62,"<>",'Player Game Log'!$C$5:$C$62,"October"),"") -> 9.27 | G9: =SUMIFS('Player Game Log'!$V$5:$V$62,'Player Game Log'!$F$5:$F$62,$B9,'Player Game Log'!$C$5:$C$62,"October") -> 10 | H9: =G9/C9 -> 10 | I9: =SUMIFS('Player Game Log'!$P$5:$P$62,'Player Game Log'!$F$5:$F$62,$B9,'Player Game Log'!$C$5:$C$62,"October") -> 4 | J9: =I9/C9 -> 4 | K9: =SUMIFS('Player Game Log'!$N$5:$N$62,'Player Game Log'!$F$5:$F$62,$B9,'Player Game Log'!$C$5:$C$62,"October") -> 3 | L9: =SUMIFS('Player Game Log'!$Q$5:$Q$62,'Player Game Log'!$F$5:$F$62,$B9,'Player Game Log'!$C$5:$C$62,"October") -> 0 | M9: =L9/C9 -> 0 | N9: =SUMIFS('Player Game Log'!$R$5:$R$62,'Player Game Log'!$F$5:$F$62,$B9,'Player Game Log'!$C$5:$C$62,"October") -> 0 | O9: =N9/C9 -> 0 | P9: =SUMIFS('Player Game Log'!$S$5:$S$62,'Player Game Log'!$F$5:$F$62,$B9,'Player Game Log'!$C$5:$C$62,"October") -> 1 | Q9: =P9/C9 -> 1 | R9: =SUMIFS('Player Game Log'!$T$5:$T$62,'Player Game Log'!$F$5:$F$62,$B9,'Player Game Log'!$C$5:$C$62,"October") -> 0 | S9: =SUMIFS('Player Game Log'!$U$5:$U$62,'Player Game Log'!$F$5:$F$62,$B9,'Player Game Log'!$C$5:$C$62,"October") -> 0 | T9: =S9/C9 -> 0 | U9: =SUMIFS('Player Game Log'!$H$5:$H$62,'Player Game Log'!$F$5:$F$62,$B9,'Player Game Log'!$C$5:$C$62,"October") -> 4 | V9: =SUMIFS('Player Game Log'!$I$5:$I$62,'Player Game Log'!$F$5:$F$62,$B9,'Player Game Log'!$C$5:$C$62,"October") -> 6 | W9: =IF(V9=0,"",U9/V9) -> 0.66666667 | X9: =SUMIFS('Player Game Log'!$J$5:$J$62,'Player Game Log'!$F$5:$F$62,$B9,'Player Game Log'!$C$5:$C$62,"October") -> 2 | Y9: =SUMIFS('Player Game Log'!$K$5:$K$62,'Player Game Log'!$F$5:$F$62,$B9,'Player Game Log'!$C$5:$C$62,"October") -> 4 | Z9: =IF(Y9=0,"",X9/Y9) -> 0.5 | AA9: =SUMIFS('Player Game Log'!$L$5:$L$62,'Player Game Log'!$F$5:$F$62,$B9,'Player Game Log'!$C$5:$C$62,"October") -> 0 | AB9: =SUMIFS('Player Game Log'!$M$5:$M$62,'Player Game Log'!$F$5:$F$62,$B9,'Player Game Log'!$C$5:$C$62,"October") -> 0 | AC9: =IF(AB9=0,"",AA9/AB9) | AD9: =IF(V9=0,"",(U9+0.5*X9)/V9) -> 0.83333333 | AE9: =IF(V9+AB9=0,"",G9/(2*(V9+0.44*AB9))) -> 0.83333333 | AF9: =IF(E9=0,"",G9/E9*40) -> 43.149946
A10: 0 | B10: Kaden Magwood | C10: =COUNTIFS('Player Game Log'!$F$5:$F$62,$B10,'Player Game Log'!$C$5:$C$62,"October") -> 2 | D10: =COUNTIFS('Player Game Log'!$F$5:$F$62,$B10,'Player Game Log'!$W$5:$W$62,"Yes",'Player Game Log'!$C$5:$C$62,"October") -> 0 | E10: =SUMIFS('Player Game Log'!$G$5:$G$62,'Player Game Log'!$F$5:$F$62,$B10,'Player Game Log'!$C$5:$C$62,"October") -> 33.08 | F10: =IFERROR(E10/COUNTIFS('Player Game Log'!$F$5:$F$62,$B10,'Player Game Log'!$G$5:$G$62,"<>",'Player Game Log'!$C$5:$C$62,"October"),"") -> 16.54 | G10: =SUMIFS('Player Game Log'!$V$5:$V$62,'Player Game Log'!$F$5:$F$62,$B10,'Player Game Log'!$C$5:$C$62,"October") -> 16 | H10: =G10/C10 -> 8 | I10: =SUMIFS('Player Game Log'!$P$5:$P$62,'Player Game Log'!$F$5:$F$62,$B10,'Player Game Log'!$C$5:$C$62,"October") -> 6 | J10: =I10/C10 -> 3 | K10: =SUMIFS('Player Game Log'!$N$5:$N$62,'Player Game Log'!$F$5:$F$62,$B10,'Player Game Log'!$C$5:$C$62,"October") -> 1 | L10: =SUMIFS('Player Game Log'!$Q$5:$Q$62,'Player Game Log'!$F$5:$F$62,$B10,'Player Game Log'!$C$5:$C$62,"October") -> 2 | M10: =L10/C10 -> 1 | N10: =SUMIFS('Player Game Log'!$R$5:$R$62,'Player Game Log'!$F$5:$F$62,$B10,'Player Game Log'!$C$5:$C$62,"October") -> 8 | O10: =N10/C10 -> 4 | P10: =SUMIFS('Player Game Log'!$S$5:$S$62,'Player Game Log'!$F$5:$F$62,$B10,'Player Game Log'!$C$5:$C$62,"October") -> 4 | Q10: =P10/C10 -> 2 | R10: =SUMIFS('Player Game Log'!$T$5:$T$62,'Player Game Log'!$F$5:$F$62,$B10,'Player Game Log'!$C$5:$C$62,"October") -> 0 | S10: =SUMIFS('Player Game Log'!$U$5:$U$62,'Player Game Log'!$F$5:$F$62,$B10,'Player Game Log'!$C$5:$C$62,"October") -> 5 | T10: =S10/C10 -> 2.5 | U10: =SUMIFS('Player Game Log'!$H$5:$H$62,'Player Game Log'!$F$5:$F$62,$B10,'Player Game Log'!$C$5:$C$62,"October") -> 6 | V10: =SUMIFS('Player Game Log'!$I$5:$I$62,'Player Game Log'!$F$5:$F$62,$B10,'Player Game Log'!$C$5:$C$62,"October") -> 12 | W10: =IF(V10=0,"",U10/V10) -> 0.5 | X10: =SUMIFS('Player Game Log'!$J$5:$J$62,'Player Game Log'!$F$5:$F$62,$B10,'Player Game Log'!$C$5:$C$62,"October") -> 3 | Y10: =SUMIFS('Player Game Log'!$K$5:$K$62,'Player Game Log'!$F$5:$F$62,$B10,'Player Game Log'!$C$5:$C$62,"October") -> 6 | Z10: =IF(Y10=0,"",X10/Y10) -> 0.5 | AA10: =SUMIFS('Player Game Log'!$L$5:$L$62,'Player Game Log'!$F$5:$F$62,$B10,'Player Game Log'!$C$5:$C$62,"October") -> 1 | AB10: =SUMIFS('Player Game Log'!$M$5:$M$62,'Player Game Log'!$F$5:$F$62,$B10,'Player Game Log'!$C$5:$C$62,"October") -> 3 | AC10: =IF(AB10=0,"",AA10/AB10) -> 0.33333333 | AD10: =IF(V10=0,"",(U10+0.5*X10)/V10) -> 0.625 | AE10: =IF(V10+AB10=0,"",G10/(2*(V10+0.44*AB10))) -> 0.6006006 | AF10: =IF(E10=0,"",G10/E10*40) -> 19.347037
A11: 11 | B11: Brigham Rogers | C11: =COUNTIFS('Player Game Log'!$F$5:$F$62,$B11,'Player Game Log'!$C$5:$C$62,"October") -> 2 | D11: =COUNTIFS('Player Game Log'!$F$5:$F$62,$B11,'Player Game Log'!$W$5:$W$62,"Yes",'Player Game Log'!$C$5:$C$62,"October") -> 2 | E11: =SUMIFS('Player Game Log'!$G$5:$G$62,'Player Game Log'!$F$5:$F$62,$B11,'Player Game Log'!$C$5:$C$62,"October") -> 48.48 | F11: =IFERROR(E11/COUNTIFS('Player Game Log'!$F$5:$F$62,$B11,'Player Game Log'!$G$5:$G$62,"<>",'Player Game Log'!$C$5:$C$62,"October"),"") -> 24.24 | G11: =SUMIFS('Player Game Log'!$V$5:$V$62,'Player Game Log'!$F$5:$F$62,$B11,'Player Game Log'!$C$5:$C$62,"October") -> 15 | H11: =G11/C11 -> 7.5 | I11: =SUMIFS('Player Game Log'!$P$5:$P$62,'Player Game Log'!$F$5:$F$62,$B11,'Player Game Log'!$C$5:$C$62,"October") -> 11 | J11: =I11/C11 -> 5.5 | K11: =SUMIFS('Player Game Log'!$N$5:$N$62,'Player Game Log'!$F$5:$F$62,$B11,'Player Game Log'!$C$5:$C$62,"October") -> 6 | L11: =SUMIFS('Player Game Log'!$Q$5:$Q$62,'Player Game Log'!$F$5:$F$62,$B11,'Player Game Log'!$C$5:$C$62,"October") -> 7 | M11: =L11/C11 -> 3.5 | N11: =SUMIFS('Player Game Log'!$R$5:$R$62,'Player Game Log'!$F$5:$F$62,$B11,'Player Game Log'!$C$5:$C$62,"October") -> 1 | O11: =N11/C11 -> 0.5 | P11: =SUMIFS('Player Game Log'!$S$5:$S$62,'Player Game Log'!$F$5:$F$62,$B11,'Player Game Log'!$C$5:$C$62,"October") -> 2 | Q11: =P11/C11 -> 1 | R11: =SUMIFS('Player Game Log'!$T$5:$T$62,'Player Game Log'!$F$5:$F$62,$B11,'Player Game Log'!$C$5:$C$62,"October") -> 3 | S11: =SUMIFS('Player Game Log'!$U$5:$U$62,'Player Game Log'!$F$5:$F$62,$B11,'Player Game Log'!$C$5:$C$62,"October") -> 5 | T11: =S11/C11 -> 2.5 | U11: =SUMIFS('Player Game Log'!$H$5:$H$62,'Player Game Log'!$F$5:$F$62,$B11,'Player Game Log'!$C$5:$C$62,"October") -> 5 | V11: =SUMIFS('Player Game Log'!$I$5:$I$62,'Player Game Log'!$F$5:$F$62,$B11,'Player Game Log'!$C$5:$C$62,"October") -> 14 | W11: =IF(V11=0,"",U11/V11) -> 0.35714286 | X11: =SUMIFS('Player Game Log'!$J$5:$J$62,'Player Game Log'!$F$5:$F$62,$B11,'Player Game Log'!$C$5:$C$62,"October") -> 0 | Y11: =SUMIFS('Player Game Log'!$K$5:$K$62,'Player Game Log'!$F$5:$F$62,$B11,'Player Game Log'!$C$5:$C$62,"October") -> 0 | Z11: =IF(Y11=0,"",X11/Y11) | AA11: =SUMIFS('Player Game Log'!$L$5:$L$62,'Player Game Log'!$F$5:$F$62,$B11,'Player Game Log'!$C$5:$C$62,"October") -> 5 | AB11: =SUMIFS('Player Game Log'!$M$5:$M$62,'Player Game Log'!$F$5:$F$62,$B11,'Player Game Log'!$C$5:$C$62,"October") -> 7 | AC11: =IF(AB11=0,"",AA11/AB11) -> 0.71428571 | AD11: =IF(V11=0,"",(U11+0.5*X11)/V11) -> 0.35714286 | AE11: =IF(V11+AB11=0,"",G11/(2*(V11+0.44*AB11))) -> 0.43911007 | AF11: =IF(E11=0,"",G11/E11*40) -> 12.376238
